Workbook

Sheet Lớp 10
A1: TỔNG KẾT THI ĐUA - TUẦN 1+2 - KHỐI 10
A2: Từ ngày: 21/08/2025 đến ngày: 12/09/2025
A4: LỚP | B4: HỌC TẬP | E4: NỀN NẾP | O4: CÁC HOẠT ĐỘNG KHÁC | S4: ĐIỂM TỔNG KẾT | T4: VỊ THỨ
B5: Tổng điểm các môn học | C5: Tổng các tiết học | D5: ĐIỂM HỌC TẬP | E5: Vắng không phép | F5: Trễ | G5: Mất trật tự | H5: Chuồn học | I5: Tác phong | J5: Trực báo | K5: Sổ sách | L5: Chào cờ | M5: Các vi phạm khác | N5: ĐIỂM NỀN NẾP | O5: Trong trường | P5: Ngoài trường | Q5: Điểm thưởng | R5: ĐIỂM HOẠT ĐỘNG
A7: 10
A8: 10/1 | B8: =300-U8 -> 300 | C8: 30 | D8: =B8 -> 300 | F8: 0.5 | N8: =SUM(E8:M8) -> 0.5 | R8: =SUM(O8:Q8) -> 0 | S8: =D8-N8+R8 -> 299.5 | T8: =RANK(S8,$S$8:$S$19,0) -> 6 | U8: 0
A9: 10/2 | B9: =300-U9 -> 300 | C9: 30 | D9: =B9 -> 300 | F9: 0.5 | M9: 0.5 | N9: =SUM(E9:M9) -> 1 | R9: =SUM(O9:Q9) -> 0 | S9: =D9-N9+R9 -> 299 | T9: =RANK(S9,$S$8:$S$19,0) -> 10 | U9: 0
A10: 10/3 | B10: =300-U10 -> 300 | C10: 30 | D10: =B10 -> 300 | I10: 0.5 | N10: =SUM(E10:M10) -> 0.5 | R10: =SUM(O10:Q10) -> 0 | S10: =D10-N10+R10 -> 299.5 | T10: =RANK(S10,$S$8:$S$19,0) -> 6 | U10: 0
A11: 10/4 | B11: =300-U11 -> 300 | C11: 30 | D11: =B11 -> 300 | F11: 2.5 | N11: =SUM(E11:M11) -> 2.5 | R11: =SUM(O11:Q11) -> 0 | S11: =D11-N11+R11 -> 297.5 | T11: =RANK(S11,$S$8:$S$19,0) -> 12 | U11: 0
A12: 10/5 | B12: =300-U12 -> 300 | C12: 30 | D12: =B12 -> 300 | N12: =SUM(E12:M12) -> 0 | R12: =SUM(O12:Q12) -> 0 | S12: =D12-N12+R12 -> 300 | T12: =RANK(S12,$S$8:$S$19,0) -> 2 | U12: 0
A13: 10/6 | B13: =300-U13 -> 300 | C13: 30 | D13: =B13 -> 300 | I13: 0.5 | N13: =SUM(E13:M13) -> 0.5 | R13: =SUM(O13:Q13) -> 0 | S13: =D13-N13+R13 -> 299.5 | T13: =RANK(S13,$S$8:$S$19,0) -> 6 | U13: 0
A14: 10/7 | B14: =300-U14 -> 300 | C14: 30 | D14: =B14 -> 300 | I14: 0.5 | N14: =SUM(E14:M14) -> 0.5 | Q14: 0.5 | R14: =SUM(O14:Q14) -> 0.5 | S14: =D14-N14+R14 -> 300 | T14: =RANK(S14,$S$8:$S$19,0) -> 2 | U14: 0
A15: 10/8 | B15: =300-U15 -> 300 | C15: 30 | D15: =B15 -> 300 | N15: =SUM(E15:M15) -> 0 | R15: =SUM(O15:Q15) -> 0 | S15: =D15-N15+R15 -> 300 | T15: =RANK(S15,$S$8:$S$19,0) -> 2 | U15: 0
A16: 10/9 | B16: =300-U16 -> 300 | C16: 30 | D16: =B16 -> 300 | N16: =SUM(E16:M16) -> 0 | R16: =SUM(O16:Q16) -> 0 | S16: =D16-N16+R16 -> 300 | T16: =RANK(S16,$S$8:$S$19,0) -> 2 | U16: 0
A17: 10/10 | B17: =300-U17 -> 300 | C17: 30 | D17: =B17 -> 300 | F17: 0.5 | N17: =SUM(E17:M17) -> 0.5 | R17: =SUM(O17:Q17) -> 0 | S17: =D17-N17+R17 -> 299.5 | T17: =RANK(S17,$S$8:$S$19,0) -> 6 | U17: 0
A18: 10/11 | B18: =300-U18 -> 300 | C18: 30 | D18: =B18 -> 300 | F18: 1 | N18: =SUM(E18:M18) -> 1 | R18: =SUM(O18:Q18) -> 0 | S18: =D18-N18+R18 -> 299 | T18: =RANK(S18,$S$8:$S$19,0) -> 10 | U18: 0
A19: 10/12 | B19: =300-U19 -> 300 | C19: 30 | D19: =B19 -> 300 | N19: =SUM(E19:M19) -> 0 | Q19: 0.5 | R19: =SUM(O19:Q19) -> 0.5 | S19: =D19-N19+R19 -> 300.5 | T19: =RANK(S19,$S$8:$S$19,0) -> 1 | U19: 0
B21: Vi phạm | H21: Quên cộng sổ đầu bài: 10/2 | N21: Điểm thưởng các lớp tham gia hoạt động văn nghệ Lễ khai giảng, Lễ chào cờ
B22: 10/1: Trễ: Anh Kiệt | N22: (+0,5): 10/7, 10/12
B23: 10/2: Trễ: Tấn Lộc
B24: 10/3: VPĐP: Quang Vinh
B25: 10/4: Trễ: An Đức, Quốc Hải, Bá Dũng, Thành Đạt, Bảo Trân
B26: 10/6: VPĐP: Trung Chính
B27: 10/7: VPTP: Thiên Thanh
B28: 10/10: Trễ: Hải Sơn
B29: 10/11: Trễ: Minh Trường, Phương Thảo
A33: TỔNG KẾT THI ĐUA - TUẦN 3 - KHỐI 10
A34: Từ ngày: 15/09/2025 đến ngày: 19/09/2025
A36: LỚP | B36: HỌC TẬP | E36: NỀN NẾP | O36: CÁC HOẠT ĐỘNG KHÁC | S36: ĐIỂM TỔNG KẾT | T36: VỊ THỨ
B37: Tổng điểm các môn học | C37: Tổng các tiết học | D37: ĐIỂM HỌC TẬP | E37: Vắng không phép | F37: Trễ | G37: Mất trật tự | H37: Chuồn học | I37: Tác phong | J37: Trực báo | K37: Sổ sách | L37: Chào cờ | M37: Các vi phạm khác | N37: ĐIỂM NỀN NẾP | O37: Trong trường | P37: Ngoài trường | Q37: Điểm thưởng | R37: ĐIỂM HOẠT ĐỘNG
A39: 10
A40: 10/1 | B40: =300-U40 -> 300 | C40: 30 | D40: =B40 -> 300 | N40: =SUM(E40:M40) -> 0 | Q40: 1.5 | R40: =SUM(O40:Q40) -> 1.5 | S40: =D40-N40+R40 -> 301.5 | T40: =RANK(S40,$S$40:$S$51,0) -> 4 | U40: 0
A41: 10/2 | B41: =300-U41 -> 300 | C41: 30 | D41: =B41 -> 300 | I41: 0.5 | N41: =SUM(E41:M41) -> 0.5 | Q41: 2.5 | R41: =SUM(O41:Q41) -> 2.5 | S41: =D41-N41+R41 -> 302 | T41: =RANK(S41,$S$40:$S$51,0) -> 2 | U41: 0
A42: 10/3 | B42: =300-U42 -> 300 | C42: 30 | D42: =B42 -> 300 | E42: 1.5 | K42: 0.5 | N42: =SUM(E42:M42) -> 2 | Q42: 2.5 | R42: =SUM(O42:Q42) -> 2.5 | S42: =D42-N42+R42 -> 300.5 | T42: =RANK(S42,$S$40:$S$51,0) -> 7 | U42: 0
A43: 10/4 | B43: =300-U43 -> 300 | C43: 30 | D43: =B43 -> 300 | N43: =SUM(E43:M43) -> 0 | Q43: 1.5 | R43: =SUM(O43:Q43) -> 1.5 | S43: =D43-N43+R43 -> 301.5 | T43: =RANK(S43,$S$40:$S$51,0) -> 4 | U43: 0
A44: 10/5 | B44: =300-U44 -> 300 | C44: 30 | D44: =B44 -> 300 | F44: 1 | N44: =SUM(E44:M44) -> 1 | Q44: 1.5 | R44: =SUM(O44:Q44) -> 1.5 | S44: =D44-N44+R44 -> 300.5 | T44: =RANK(S44,$S$40:$S$51,0) -> 7 | U44: 0
A45: 10/6 | B45: =300-U45 -> 300 | C45: 30 | D45: =B45 -> 300 | E45: 3 | F45: 0.5 | N45: =SUM(E45:M45) -> 3.5 | Q45: 1.5 | R45: =SUM(O45:Q45) -> 1.5 | S45: =D45-N45+R45 -> 298 | T45: =RANK(S45,$S$40:$S$51,0) -> 11 | U45: 0
A46: 10/7 | B46: =300-U46 -> 299 | C46: 30 | D46: =B46 -> 299 | I46: 0.5 | N46: =SUM(E46:M46) -> 0.5 | Q46: 2.5 | R46: =SUM(O46:Q46) -> 2.5 | S46: =D46-N46+R46 -> 301 | T46: =RANK(S46,$S$40:$S$51,0) -> 6 | U46: 1
A47: 10/8 | B47: =300-U47 -> 300 | C47: 30 | D47: =B47 -> 300 | N47: =SUM(E47:M47) -> 0 | Q47: 2.5 | R47: =SUM(O47:Q47) -> 2.5 | S47: =D47-N47+R47 -> 302.5 | T47: =RANK(S47,$S$40:$S$51,0) -> 1 | U47: 0
A48: 10/9 | B48: =300-U48 -> 300 | C48: 30 | D48: =B48 -> 300 | I48: 2 | N48: =SUM(E48:M48) -> 2 | Q48: 0.5 | R48: =SUM(O48:Q48) -> 0.5 | S48: =D48-N48+R48 -> 298.5 | T48: =RANK(S48,$S$40:$S$51,0) -> 10 | U48: 0
...

Sheet Lớp 11
A1: TỔNG KẾT THI ĐUA - TUẦN 1 + 2 - KHỐI 11
A2: Từ ngày: 21/08/2025 đến ngày: 12/09/2025
A4: LỚP | B4: HỌC TẬP | E4: NỀN NẾP | O4: CÁC HOẠT ĐỘNG KHÁC | S4: ĐIỂM TỔNG KẾT | T4: VỊ THỨ
B5: Tổng điểm các môn học | C5: Tổng các tiết học | D5: ĐIỂM HỌC TẬP | E5: Vắng không phép | F5: Trễ | G5: Mất trật tự | H5: Chuồn học | I5: Tác phong | J5: Trực báo | K5: Sổ sách | L5: Chào cờ | M5: Các vi phạm khác | N5: ĐIỂM NỀN NẾP | O5: Trong trường | P5: Ngoài trường | Q5: Điểm thưởng | R5: ĐIỂM HOẠT ĐỘNG
A7: 11
A8: 11/1 | B8: =300-U8 -> 300 | C8: 30 | D8: =B8 -> 300 | I8: 0.5 | M8: 1 | N8: =SUM(E8:M8) -> 1.5 | Q8: 2 | R8: =SUM(O8:Q8) -> 2 | S8: =D8-N8+R8 -> 300.5 | T8: =RANK(S8,$S$8:$S$21,0) -> 1 | U8: 0
A9: 11/2 | B9: =300-U9 -> 300 | C9: 30 | D9: =B9 -> 300 | E9: 1.5 | F9: 0.5 | N9: =SUM(E9:M9) -> 2 | Q9: 2 | R9: =SUM(O9:Q9) -> 2 | S9: =D9-N9+R9 -> 300 | T9: =RANK(S9,$S$8:$S$21,0) -> 2 | U9: 0
A10: 11/3 | B10: =300-U10 -> 300 | C10: 30 | D10: =B10 -> 300 | F10: 1 | N10: =SUM(E10:M10) -> 1 | R10: =SUM(O10:Q10) -> 0 | S10: =D10-N10+R10 -> 299 | T10: =RANK(S10,$S$8:$S$21,0) -> 10 | U10: 0
A11: 11/4 | B11: =300-U11 -> 300 | C11: 30 | D11: =B11 -> 300 | N11: =SUM(E11:M11) -> 0 | R11: =SUM(O11:Q11) -> 0 | S11: =D11-N11+R11 -> 300 | T11: =RANK(S11,$S$8:$S$21,0) -> 2 | U11: 0
A12: 11/5 | B12: =300-U12 -> 300 | C12: 30 | D12: =B12 -> 300 | I12: 0.5 | N12: =SUM(E12:M12) -> 0.5 | Q12: 0.5 | R12: =SUM(O12:Q12) -> 0.5 | S12: =D12-N12+R12 -> 300 | T12: =RANK(S12,$S$8:$S$21,0) -> 2 | U12: 0
A13: 11/6 | B13: =300-U13 -> 300 | C13: 30 | D13: =B13 -> 300 | E13: 3 | F13: 0.5 | I13: 1.5 | N13: =SUM(E13:M13) -> 5 | R13: =SUM(O13:Q13) -> 0 | S13: =D13-N13+R13 -> 295 | T13: =RANK(S13,$S$8:$S$21,0) -> 14 | U13: 0
A14: 11/7 | B14: =300-U14 -> 300 | C14: 30 | D14: =B14 -> 300 | N14: =SUM(E14:M14) -> 0 | R14: =SUM(O14:Q14) -> 0 | S14: =D14-N14+R14 -> 300 | T14: =RANK(S14,$S$8:$S$21,0) -> 2 | U14: 0
A15: 11/8 | B15: =300-U15 -> 300 | C15: 30 | D15: =B15 -> 300 | E15: 1.5 | N15: =SUM(E15:M15) -> 1.5 | R15: =SUM(O15:Q15) -> 0 | S15: =D15-N15+R15 -> 298.5 | T15: =RANK(S15,$S$8:$S$21,0) -> 11 | U15: 0
A16: 11/9 | B16: =300-U16 -> 300 | C16: 30 | D16: =B16 -> 300 | F16: 0.5 | I16: 0.5 | N16: =SUM(E16:M16) -> 1 | Q16: 0.5 | R16: =SUM(O16:Q16) -> 0.5 | S16: =D16-N16+R16 -> 299.5 | T16: =RANK(S16,$S$8:$S$21,0) -> 7 | U16: 0
A17: 11/10 | B17: =300-U17 -> 300 | C17: 30 | D17: =B17 -> 300 | F17: 0.5 | N17: =SUM(E17:M17) -> 0.5 | R17: =SUM(O17:Q17) -> 0 | S17: =D17-N17+R17 -> 299.5 | T17: =RANK(S17,$S$8:$S$21,0) -> 7 | U17: 0
A18: 11/11 | B18: =300-U18 -> 300 | C18: 30 | D18: =B18 -> 300 | M18: 0.5 | N18: =SUM(E18:M18) -> 0.5 | Q18: 0.5 | R18: =SUM(O18:Q18) -> 0.5 | S18: =D18-N18+R18 -> 300 | T18: =RANK(S18,$S$8:$S$21,0) -> 2 | U18: 0
A19: 11/12 | B19: =300-U19 -> 300 | C19: 30 | D19: =B19 -> 300 | E19: 3 | N19: =SUM(E19:M19) -> 3 | Q19: 0.5 | R19: =SUM(O19:Q19) -> 0.5 | S19: =D19-N19+R19 -> 297.5 | T19: =RANK(S19,$S$8:$S$21,0) -> 12 | U19: 0
A20: 11/13 | B20: =300-U20 -> 300 | C20: 30 | D20: =B20 -> 300 | I20: 0.5 | N20: =SUM(E20:M20) -> 0.5 | R20: =SUM(O20:Q20) -> 0 | S20: =D20-N20+R20 -> 299.5 | T20: =RANK(S20,$S$8:$S$21,0) -> 7 | U20: 0
A21: 11/14 | B21: =300-U21 -> 300 | C21: 30 | D21: =B21 -> 300 | F21: 2 | M21: 1 | N21: =SUM(E21:M21) -> 3 | Q21: 0.5 | R21: =SUM(O21:Q21) -> 0.5 | S21: =D21-N21+R21 -> 297.5 | T21: =RANK(S21,$S$8:$S$21,0) -> 12 | U21: 0
B23: Vi Phạm
B24: 11/1: VPĐP: Huy Hùng Hút thuốc lá: Lâm Hiếu | K24: Không tham gia tập huấn (-1): 11/14
B25: 11/2: Vắng KP: Tiến Thạnh ( 28/8) Trễ: Khánh Việt
B26: 11/3: Trễ: Linh Đan, Thúy Trúc | K26: Điểm thưởng các lớp tham gia hoạt động văn nghệ Lễ khai giảng, Lễ chào cờ
K27: (+2): 11/1, 11/2
B28: 11/5: VPTP: Nguyên Khoa | K28: (+0,5): 11/5, 11/9, 11/11, 11/12, 11/14
B29: 11/6: Vắng KP: Minh khôi, Quốc Huy ( 28/8) Trễ: Đình Quyền VPTP: Bảo Quân, Quốc Huy VPĐP: Quỳnh Anh
B31: 11/8: Vắng KP: Việt Thắng ( 28/8)
B32: 11/9: Trễ: Thảo Linh VPTP: Bảo Trâm
B33: 11/10: Trễ: Trung Ngọc
B34: 11/11: KMBH: Bảo Trí
B35: 11/12: Vắng KP: Long Nhật , Thủy Tiên ( 28/8)
B36: 11/13: VPĐP: Quốc Bảo
B37: 11/14: Trễ: Hoàng Anh, Bảo Nam, Bích Ngọc, Uyên Ngân
A41: TỔNG KẾT THI ĐUA - TUẦN 3 - KHỐI 11
A42: Từ ngày: 15/09/2025 đến ngày: 19/09/2025
A44: LỚP | B44: HỌC TẬP | E44: NỀN NẾP | O44: CÁC HOẠT ĐỘNG KHÁC | S44: ĐIỂM TỔNG KẾT | T44: VỊ THỨ
B45: Tổng điểm các môn học | C45: Tổng các tiết học | D45: ĐIỂM HỌC TẬP | E45: Vắng không phép | F45: Trễ | G45: Mất trật tự | H45: Chuồn học | I45: Tác phong | J45: Trực báo | K45: Sổ sách | L45: Chào cờ | M45: Các vi phạm khác | N45: ĐIỂM NỀN NẾP | O45: Trong trường | P45: Ngoài trường | Q45: Điểm thưởng | R45: ĐIỂM HOẠT ĐỘNG
A47: 11
A48: 11/1 | B48: =300-U48 -> 299 | C48: 30 | D48: =B48 -> 299 | N48: =SUM(E48:M48) -> 0 | Q48: 1.5 | R48: =SUM(O48:Q48) -> 1.5 | S48: =D48-N48+R48 -> 300.5 | T48: =RANK(S48,$S$48:$S$61,0) -> 11 | U48: 1
A49: 11/2 | B49: =300-U49 -> 300 | C49: 30 | D49: =B49 -> 300 | L49: 0.5 | N49: =SUM(E49:M49) -> 0.5 | Q49: 3 | R49: =SUM(O49:Q49) -> 3 | S49: =D49-N49+R49 -> 302.5 | T49: =RANK(S49,$S$48:$S$61,0) -> 2 | U49: 0
...

Sheet Lớp 12
A1: TỔNG KẾT THI ĐUA - TUẦN 1 + 2 - KHỐI 12
A2: Từ ngày: 21/08/2025 đến ngày: 12/09/2025
A4: LỚP | B4: HỌC TẬP | E4: NỀN NẾP | O4: CÁC HOẠT ĐỘNG KHÁC | S4: ĐIỂM TỔNG KẾT | T4: VỊ THỨ
B5: Tổng điểm các môn học | C5: Tổng các tiết học | D5: ĐIỂM HỌC TẬP | E5: Vắng không phép | F5: Trễ | G5: Mất trật tự | H5: Chuồn học | I5: Tác phong | J5: Trực báo | K5: Sổ sách | L5: Chào cờ | M5: Các vi phạm khác | N5: ĐIỂM NỀN NẾP | O5: Trong trường | P5: Ngoài trường | Q5: Điểm thưởng | R5: ĐIỂM HOẠT ĐỘNG
A7: 12
A8: 12/1 | B8: =300-U8 -> 300 | C8: 30 | D8: =B8 -> 300 | F8: 1 | N8: =SUM(E8:M8) -> 1 | Q8: 3 | R8: =SUM(O8:Q8) -> 3 | S8: =D8-N8+R8 -> 302 | T8: =RANK(S8,$S$8:$S$21,0) -> 1 | U8: 0
A9: 12/2 | B9: =300-U9 -> 300 | C9: 30 | D9: =B9 -> 300 | E9: 3 | F9: 1 | I9: 3 | N9: =SUM(E9:M9) -> 7 | R9: =SUM(O9:Q9) -> 0 | S9: =D9-N9+R9 -> 293 | T9: =RANK(S9,$S$8:$S$21,0) -> 14 | U9: 0
A10: 12/3 | B10: =300-U10 -> 300 | C10: 30 | D10: =B10 -> 300 | F10: 0.5 | I10: 0.5 | N10: =SUM(E10:M10) -> 1 | R10: =SUM(O10:Q10) -> 0 | S10: =D10-N10+R10 -> 299 | T10: =RANK(S10,$S$8:$S$21,0) -> 4 | U10: 0
A11: 12/4 | B11: =300-U11 -> 300 | C11: 30 | D11: =B11 -> 300 | E11: 6 | F11: 0.5 | I11: 0.5 | N11: =SUM(E11:M11) -> 7 | Q11: 0.5 | R11: =SUM(O11:Q11) -> 0.5 | S11: =D11-N11+R11 -> 293.5 | T11: =RANK(S11,$S$8:$S$21,0) -> 13 | U11: 0
A12: 12/5 | B12: =300-U12 -> 300 | C12: 30 | D12: =B12 -> 300 | F12: 0.5 | N12: =SUM(E12:M12) -> 0.5 | Q12: 0.5 | R12: =SUM(O12:Q12) -> 0.5 | S12: =D12-N12+R12 -> 300 | T12: =RANK(S12,$S$8:$S$21,0) -> 2 | U12: 0
A13: 12/6 | B13: =300-U13 -> 300 | C13: 30 | D13: =B13 -> 300 | E13: 1.5 | N13: =SUM(E13:M13) -> 1.5 | R13: =SUM(O13:Q13) -> 0 | S13: =D13-N13+R13 -> 298.5 | T13: =RANK(S13,$S$8:$S$21,0) -> 8 | U13: 0
A14: 12/7 | B14: =300-U14 -> 300 | C14: 30 | D14: =B14 -> 300 | F14: 0.5 | I14: 0.5 | N14: =SUM(E14:M14) -> 1 | R14: =SUM(O14:Q14) -> 0 | S14: =D14-N14+R14 -> 299 | T14: =RANK(S14,$S$8:$S$21,0) -> 4 | U14: 0
A15: 12/8 | B15: =300-U15 -> 300 | C15: 30 | D15: =B15 -> 300 | E15: 4.5 | F15: 0.5 | N15: =SUM(E15:M15) -> 5 | Q15: 0.5 | R15: =SUM(O15:Q15) -> 0.5 | S15: =D15-N15+R15 -> 295.5 | T15: =RANK(S15,$S$8:$S$21,0) -> 11 | U15: 0
A16: 12/9 | B16: =300-U16 -> 300 | C16: 30 | D16: =B16 -> 300 | I16: 1.5 | N16: =SUM(E16:M16) -> 1.5 | Q16: 0.5 | R16: =SUM(O16:Q16) -> 0.5 | S16: =D16-N16+R16 -> 299 | T16: =RANK(S16,$S$8:$S$21,0) -> 4 | U16: 0
A17: 12/10 | B17: =300-U17 -> 300 | C17: 30 | D17: =B17 -> 300 | I17: 1 | N17: =SUM(E17:M17) -> 1 | R17: =SUM(O17:Q17) -> 0 | S17: =D17-N17+R17 -> 299 | T17: =RANK(S17,$S$8:$S$21,0) -> 4 | U17: 0
A18: 12/11 | B18: =300-U18 -> 300 | C18: 30 | D18: =B18 -> 300 | E18: 4.5 | N18: =SUM(E18:M18) -> 4.5 | R18: =SUM(O18:Q18) -> 0 | S18: =D18-N18+R18 -> 295.5 | T18: =RANK(S18,$S$8:$S$21,0) -> 11 | U18: 0
A19: 12/12 | B19: =300-U19 -> 300 | C19: 30 | D19: =B19 -> 300 | I19: 1 | N19: =SUM(E19:M19) -> 1 | Q19: 0.5 | R19: =SUM(O19:Q19) -> 0.5 | S19: =D19-N19+R19 -> 299.5 | T19: =RANK(S19,$S$8:$S$21,0) -> 3 | U19: 0
A20: 12/13 | B20: =300-U20 -> 300 | C20: 30 | D20: =B20 -> 300 | F20: 1 | I20: 2 | N20: =SUM(E20:M20) -> 3 | Q20: 0.5 | R20: =SUM(O20:Q20) -> 0.5 | S20: =D20-N20+R20 -> 297.5 | T20: =RANK(S20,$S$8:$S$21,0) -> 9 | U20: 0
A21: 12/14 | B21: =300-U21 -> 300 | C21: 30 | D21: =B21 -> 300 | E21: 3 | F21: 0.5 | N21: =SUM(E21:M21) -> 3.5 | Q21: 0.5 | R21: =SUM(O21:Q21) -> 0.5 | S21: =D21-N21+R21 -> 297 | T21: =RANK(S21,$S$8:$S$21,0) -> 10 | U21: 0
B23: Vi phạm: | L23: Điểm thưởng các lớp tham gia hoạt động văn nghệ Lễ khai giảng, Lễ chào cờ
B24: 12/1: Trễ: Bá Quân(08/9), Nguyên Quân (09/9) | L24: (+1): 12/1
B25: 12/2: Vắng KP: Lê Huy, Xuân Khải (29/8) VPTPĐP: Anh Nhật, Minh Quân,Tùng Nhân, Bảo Nhật, Minh Trí (28/8+ 10/9) Trễ: Duy Tài (29/8) Thanh Quang (11/9) | L25: (+0,5): 12/4, 12/5, 12/8, 12/9, 12/12, 12/13, 12/14
B26: 12/3: Trễ: Công Tiến(29/8) VPĐP: Quốc Đạt (12/9) | L26: Điểm thưởng lớp tổ chức ĐH Chi đoàn mẫu
B27: 12/4: Vắng KP: Quang Thiện (29/8), Thành Đạt, Thành Nhân, Thái Quý (29/8) VPTP: Minh Sơn (09/9) Trễ: Bảo Minh (11/9) | L27: (+2): 12/1
B28: 12/5: Trễ: Diễm Tú (29/8)
B29: 12/6: Vắng KP: Ngọc Trân (29/8)
B30: 12/7: Trễ: Nam Khánh (29/8) VPĐP: Thanh Trúc (29/8)
B31: 12/8: Đan Nhã (29/8), Đôn Nhật (29/8), Đăng Quân (29/8) Trễ: Bảo Ngọc (11/9)
B32: 12/9: VPĐPTP: Quang Vinh (28/8) , Đắc Quang (29/8) Gia Minh (10/9)
B33: 12/10: VPĐP: Chiêu Nguyên, Ngọc Thanh (28/8)
B34: 12/11: Vắng KP: Thùy Linh, Đại Sơn, Chơn Vinh (29/8)
B35: 12/12: VPTPĐP: Mỹ Huyền, Bảo Linh (28/8)
B36: 12/13: VPTP: Quỳnh Anh, Bảo Ngọc (29/8) Trễ + VPĐP: Bảo Ngọc (09/9) Trễ Hải Anh (09/9)
B37: 12/14: Vắng KP: Khánh Châu, Bảo Hân(29/8) Trễ: Nhật Liên
A41: TỔNG KẾT THI ĐUA - TUẦN 3 - KHỐI 12
A42: Từ ngày: 15/09/2025 đến ngày: 19/09/2025
A44: LỚP | B44: HỌC TẬP | E44: NỀN NẾP | O44: CÁC HOẠT ĐỘNG KHÁC | S44: ĐIỂM TỔNG KẾT | T44: VỊ THỨ
B45: Tổng điểm các môn học | C45: Tổng các tiết học | D45: ĐIỂM HỌC TẬP | E45: Vắng không phép | F45: Trễ | G45: Mất trật tự | H45: Chuồn học | I45: Tác phong | J45: Trực báo | K45: Sổ sách | L45: Chào cờ | M45: Các vi phạm khác | N45: ĐIỂM NỀN NẾP | O45: Trong trường | P45: Ngoài trường | Q45: Điểm thưởng | R45: ĐIỂM HOẠT ĐỘNG
A47: 12
A48: 12/1 | B48: =300-U48 -> 300 | C48: 30 | D48: =B48 -> 300 | E48: 1.5 | I48: 0.5 | N48: =SUM(E48:M48) -> 2 | Q48: 2 | R48: =SUM(O48:Q48) -> 2 | S48: =D48-N48+R48 -> 300 | T48: =RANK(S48,$S$48:$S$61,0) -> 11 | U48: 0
...

Sheet Phong trào 1
A1: TRƯỜNG THPT NGUYỄN HUỆ
A2: ĐOÀN TRƯỜNG THPT NGUYỄN HUỆ
A4: PHONG TRÀO SỐ 1 - KHỐI 10 TỪ NGÀY 6/9/2025 ĐẾN NGÀY 24/10/2025
A7: Khối 10 | B7: Tuần 1+2 | C7: Tuần 3 | D7: Tuần 4 | E7: Tuần 5 | F7: Tuần 6 | G7: Tuần 7 | H7: Tuần 8 | I7: Trung bình | J7: Vị thứ
A8: 45667 | B8: ='Lớp 10'!S8 -> 299.5 | C8: ='Lớp 10'!S40 -> 301.5 | D8: ='Lớp 10'!S74 -> 297.5 | E8: ='Lớp 10'!S106 -> 297 | F8: ='Lớp 10'!S140 -> 301 | G8: ='Lớp 10'!S167 -> 297 | H8: ='Lớp 10'!S200 -> 300 | I8: =ROUND(AVERAGE(B8:H8),2) -> 299.07 | J8: =RANK(I8,$I$8:$I$19,0) -> 7
A9: 45698 | B9: ='Lớp 10'!S9 -> 299 | C9: ='Lớp 10'!S41 -> 302 | D9: ='Lớp 10'!S75 -> 300 | E9: ='Lớp 10'!S107 -> 301 | F9: ='Lớp 10'!S141 -> 301 | G9: ='Lớp 10'!S168 -> 298.5 | H9: ='Lớp 10'!S201 -> 299 | I9: =ROUND(AVERAGE(B9:H9),2) -> 300.07 | J9: =RANK(I9,$I$8:$I$19,0) -> 1
A10: 45726 | B10: ='Lớp 10'!S10 -> 299.5 | C10: ='Lớp 10'!S42 -> 300.5 | D10: ='Lớp 10'!S76 -> 298 | E10: ='Lớp 10'!S108 -> 296 | F10: ='Lớp 10'!S142 -> 299 | G10: ='Lớp 10'!S169 -> 297 | H10: ='Lớp 10'!S202 -> 300 | I10: =ROUND(AVERAGE(B10:H10),2) -> 298.57 | J10: =RANK(I10,$I$8:$I$19,0) -> 12
A11: 45757 | B11: ='Lớp 10'!S11 -> 297.5 | C11: ='Lớp 10'!S43 -> 301.5 | D11: ='Lớp 10'!S77 -> 299.5 | E11: ='Lớp 10'!S109 -> 299.5 | F11: ='Lớp 10'!S143 -> 299.5 | G11: ='Lớp 10'!S170 -> 298.5 | H11: ='Lớp 10'!S203 -> 299.5 | I11: =ROUND(AVERAGE(B11:H11),2) -> 299.36 | J11: =RANK(I11,$I$8:$I$19,0) -> 6
A12: 45787 | B12: ='Lớp 10'!S12 -> 300 | C12: ='Lớp 10'!S44 -> 300.5 | D12: ='Lớp 10'!S78 -> 297.5 | E12: ='Lớp 10'!S110 -> 296.5 | F12: ='Lớp 10'!S144 -> 299.5 | G12: ='Lớp 10'!S171 -> 299.5 | H12: ='Lớp 10'!S204 -> 299 | I12: =ROUND(AVERAGE(B12:H12),2) -> 298.93 | J12: =RANK(I12,$I$8:$I$19,0) -> 9
A13: 45818 | B13: ='Lớp 10'!S13 -> 299.5 | C13: ='Lớp 10'!S45 -> 298 | D13: ='Lớp 10'!S79 -> 299.5 | E13: ='Lớp 10'!S111 -> 299 | F13: ='Lớp 10'!S145 -> 300.5 | G13: ='Lớp 10'!S172 -> 298 | H13: ='Lớp 10'!S205 -> 297 | I13: =ROUND(AVERAGE(B13:H13),2) -> 298.79 | J13: =RANK(I13,$I$8:$I$19,0) -> 11
A14: 45848 | B14: ='Lớp 10'!S14 -> 300 | C14: ='Lớp 10'!S46 -> 301 | D14: ='Lớp 10'!S80 -> 299 | E14: ='Lớp 10'!S112 -> 301 | F14: ='Lớp 10'!S146 -> 299 | G14: ='Lớp 10'!S173 -> 299.5 | H14: ='Lớp 10'!S206 -> 300 | I14: =ROUND(AVERAGE(B14:H14),2) -> 299.93 | J14: =RANK(I14,$I$8:$I$19,0) -> 3
A15: 45879 | B15: ='Lớp 10'!S15 -> 300 | C15: ='Lớp 10'!S47 -> 302.5 | D15: ='Lớp 10'!S81 -> 299.5 | E15: ='Lớp 10'!S113 -> 296 | F15: ='Lớp 10'!S147 -> 301 | G15: ='Lớp 10'!S174 -> 300 | H15: ='Lớp 10'!S207 -> 300 | I15: =ROUND(AVERAGE(B15:H15),2) -> 299.86 | J15: =RANK(I15,$I$8:$I$19,0) -> 4
A16: 45910 | B16: ='Lớp 10'!S16 -> 300 | C16: ='Lớp 10'!S48 -> 298.5 | D16: ='Lớp 10'!S82 -> 296 | E16: ='Lớp 10'!S114 -> 300 | F16: ='Lớp 10'!S148 -> 300.5 | G16: ='Lớp 10'!S175 -> 298 | H16: ='Lớp 10'!S208 -> 300 | I16: =ROUND(AVERAGE(B16:H16),2) -> 299 | J16: =RANK(I16,$I$8:$I$19,0) -> 8
A17: 45940 | B17: ='Lớp 10'!S17 -> 299.5 | C17: ='Lớp 10'!S49 -> 302 | D17: ='Lớp 10'!S83 -> 299.5 | E17: ='Lớp 10'!S115 -> 302.5 | F17: ='Lớp 10'!S149 -> 298.5 | G17: ='Lớp 10'!S176 -> 299 | H17: ='Lớp 10'!S209 -> 299 | I17: =ROUND(AVERAGE(B17:H17),2) -> 300 | J17: =RANK(I17,$I$8:$I$19,0) -> 2
A18: 45971 | B18: ='Lớp 10'!S18 -> 299 | C18: ='Lớp 10'!S50 -> 298 | D18: ='Lớp 10'!S84 -> 297.5 | E18: ='Lớp 10'!S116 -> 299 | F18: ='Lớp 10'!S150 -> 300 | G18: ='Lớp 10'!S177 -> 299.5 | H18: ='Lớp 10'!S210 -> 299.5 | I18: =ROUND(AVERAGE(B18:H18),2) -> 298.93 | J18: =RANK(I18,$I$8:$I$19,0) -> 9
A19: 46001 | B19: ='Lớp 10'!S19 -> 300.5 | C19: ='Lớp 10'!S51 -> 300 | D19: ='Lớp 10'!S85 -> 298.5 | E19: ='Lớp 10'!S117 -> 298.5 | F19: ='Lớp 10'!S151 -> 301 | G19: ='Lớp 10'!S178 -> 299.5 | H19: ='Lớp 10'!S211 -> 300 | I19: =ROUND(AVERAGE(B19:H19),2) -> 299.71 | J19: =RANK(I19,$I$8:$I$19,0) -> 5
E21: TP. Huế, ngày 10 tháng 11 năm 2025
A22: XÁC NHẬN CỦA BGH | E22: T/M BCH ĐOÀN TRƯỜNG
A23: Hiệu trưởng | E23: Bí thư
A27: Đặng Đức Tuệ | E27: Dương Phước Dũng
A30: TRƯỜNG THPT NGUYỄN HUỆ
A31: ĐOÀN TRƯỜNG THPT NGUYỄN HUỆ
A33: PHONG TRÀO SỐ 1 - KHỐI 11 TỪ NGÀY 6/9/2025 ĐẾN NGÀY 24/10/2025
A36: Khối 11 | B36: Tuần 1+2 | C36: Tuần 3 | D36: Tuần 4 | E36: Tuần 5 | F36: Tuần 6 | G36: Tuần 7 | H36: Tuần 8 | I36: Trung bình | J36: Vị thứ
A37: 45668 | B37: ='Lớp 11'!S8 -> 300.5 | C37: ='Lớp 11'!S48 -> 300.5 | D37: ='Lớp 11'!S86 -> 298 | E37: ='Lớp 11'!S124 -> 302 | F37: ='Lớp 11'!S161 -> 301 | G37: ='Lớp 11'!S197 -> 300.5 | H37: ='Lớp 11'!S233 -> 301.5 | I37: =ROUND(AVERAGE(B37:H37),2) -> 300.57 | J37: =RANK(I37,$I$37:$I$50,0) -> 7
A38: 45699 | B38: ='Lớp 11'!S9 -> 300 | C38: ='Lớp 11'!S49 -> 302.5 | D38: ='Lớp 11'!S87 -> 298.5 | E38: ='Lớp 11'!S125 -> 300 | F38: ='Lớp 11'!S162 -> 298.5 | G38: ='Lớp 11'!S198 -> 301 | H38: ='Lớp 11'!S234 -> 300 | I38: =ROUND(AVERAGE(B38:H38),2) -> 300.07 | J38: =RANK(I38,$I$37:$I$50,0) -> 10
A39: 45727 | B39: ='Lớp 11'!S10 -> 299 | C39: ='Lớp 11'!S50 -> 302.5 | D39: ='Lớp 11'!S88 -> 298 | E39: ='Lớp 11'!S126 -> 307 | F39: ='Lớp 11'!S163 -> 298.5 | G39: ='Lớp 11'!S199 -> 302 | H39: ='Lớp 11'!S235 -> 299.5 | I39: =ROUND(AVERAGE(B39:H39),2) -> 300.93 | J39: =RANK(I39,$I$37:$I$50,0) -> 2
A40: 45758 | B40: ='Lớp 11'!S11 -> 300 | C40: ='Lớp 11'!S51 -> 304 | D40: ='Lớp 11'!S89 -> 299.5 | E40: ='Lớp 11'!S127 -> 301.5 | F40: ='Lớp 11'!S164 -> 298 | G40: ='Lớp 11'!S200 -> 303 | H40: ='Lớp 11'!S236 -> 300.5 | I40: =ROUND(AVERAGE(B40:H40),2) -> 300.93 | J40: =RANK(I40,$I$37:$I$50,0) -> 2
A41: 45788 | B41: ='Lớp 11'!S12 -> 300 | C41: ='Lớp 11'!S52 -> 302.5 | D41: ='Lớp 11'!S90 -> 300.5 | E41: ='Lớp 11'!S128 -> 301 | F41: ='Lớp 11'!S165 -> 301 | G41: ='Lớp 11'!S201 -> 300.5 | H41: ='Lớp 11'!S237 -> 301 | I41: =ROUND(AVERAGE(B41:H41),2) -> 300.93 | J41: =RANK(I41,$I$37:$I$50,0) -> 2
A42: 45819 | B42: ='Lớp 11'!S13 -> 295 | C42: ='Lớp 11'!S53 -> 294.5 | D42: ='Lớp 11'!S91 -> 297.5 | E42: ='Lớp 11'!S129 -> 297 | F42: ='Lớp 11'!S166 -> 289.5 | G42: ='Lớp 11'!S202 -> 299.5 | H42: ='Lớp 11'!S238 -> 298.5 | I42: =ROUND(AVERAGE(B42:H42),2) -> 295.93 | J42: =RANK(I42,$I$37:$I$50,0) -> 14
A43: 45849 | B43: ='Lớp 11'!S14 -> 300 | C43: ='Lớp 11'!S54 -> 301.5 | D43: ='Lớp 11'!S92 -> 298.5 | E43: ='Lớp 11'!S130 -> 300.5 | F43: ='Lớp 11'!S167 -> 299.5 | G43: ='Lớp 11'!S203 -> 300.5 | H43: ='Lớp 11'!S239 -> 302.5 | I43: =ROUND(AVERAGE(B43:H43),2) -> 300.43 | J43: =RANK(I43,$I$37:$I$50,0) -> 8
A44: 45880 | B44: ='Lớp 11'!S15 -> 298.5 | C44: ='Lớp 11'!S55 -> 300.5 | D44: ='Lớp 11'!S93 -> 297.5 | E44: ='Lớp 11'!S131 -> 299.5 | F44: ='Lớp 11'!S168 -> 300.5 | G44: ='Lớp 11'!S204 -> 299 | H44: ='Lớp 11'!S240 -> 299.5 | I44: =ROUND(AVERAGE(B44:H44),2) -> 299.29 | J44: =RANK(I44,$I$37:$I$50,0) -> 12
A45: 45911 | B45: ='Lớp 11'!S16 -> 299.5 | C45: ='Lớp 11'!S56 -> 301 | D45: ='Lớp 11'!S94 -> 298 | E45: ='Lớp 11'!S132 -> 300.5 | F45: ='Lớp 11'!S169 -> 297.5 | G45: ='Lớp 11'!S205 -> 300.5 | H45: ='Lớp 11'!S241 -> 300 | I45: =ROUND(AVERAGE(B45:H45),2) -> 299.57 | J45: =RANK(I45,$I$37:$I$50,0) -> 11
A46: 45941 | B46: ='Lớp 11'!S17 -> 299.5 | C46: ='Lớp 11'!S57 -> 302.5 | D46: ='Lớp 11'!S95 -> 299 | E46: ='Lớp 11'!S133 -> 302 | F46: ='Lớp 11'!S170 -> 300 | G46: ='Lớp 11'!S206 -> 301 | H46: ='Lớp 11'!S242 -> 303.5 | I46: =ROUND(AVERAGE(B46:H46),2) -> 301.07 | J46: =RANK(I46,$I$37:$I$50,0) -> 1
A47: 45972 | B47: ='Lớp 11'!S18 -> 300 | C47: ='Lớp 11'!S58 -> 301 | D47: ='Lớp 11'!S96 -> 299 | E47: ='Lớp 11'!S134 -> 300.5 | F47: ='Lớp 11'!S171 -> 301 | G47: ='Lớp 11'!S207 -> 301.5 | H47: ='Lớp 11'!S243 -> 301.5 | I47: =ROUND(AVERAGE(B47:H47),2) -> 300.64 | J47: =RANK(I47,$I$37:$I$50,0) -> 5
A48: 46002 | B48: ='Lớp 11'!S19 -> 297.5 | C48: ='Lớp 11'!S59 -> 302 | D48: ='Lớp 11'!S97 -> 298.5 | E48: ='Lớp 11'!S135 -> 301 | F48: ='Lớp 11'!S172 -> 301 | G48: ='Lớp 11'!S208 -> 301 | H48: ='Lớp 11'!S244 -> 301.5 | I48: =ROUND(AVERAGE(B48:H48),2) -> 300.36 | J48: =RANK(I48,$I$37:$I$50,0) -> 9
A49: 11/13 | B49: ='Lớp 11'!S20 -> 299.5 | C49: ='Lớp 11'!S60 -> 302 | D49: ='Lớp 11'!S98 -> 299 | E49: ='Lớp 11'!S136 -> 301.5 | F49: ='Lớp 11'!S173 -> 301 | G49: ='Lớp 11'!S209 -> 300.5 | H49: ='Lớp 11'!S245 -> 301 | I49: =ROUND(AVERAGE(B49:H49),2) -> 300.64 | J49: =RANK(I49,$I$37:$I$50,0) -> 5
A50: 11/14 | B50: ='Lớp 11'!S21 -> 297.5 | C50: ='Lớp 11'!S61 -> 300 | D50: ='Lớp 11'!S99 -> 298 | E50: ='Lớp 11'!S137 -> 298.5 | F50: ='Lớp 11'!S174 -> 299 | G50: ='Lớp 11'!S210 -> 300.5 | H50: ='Lớp 11'!S246 -> 300.5 | I50: =ROUND(AVERAGE(B50:H50),2) -> 299.14 | J50: =RANK(I50,$I$37:$I$50,0) -> 13
E52: TP. Huế, ngày 10 tháng 11 năm 2025
A53: XÁC NHẬN CỦA BGH | E53: T/M BCH ĐOÀN TRƯỜNG
...

Sheet Phong trào 2
A1: TRƯỜNG THPT NGUYỄN HUỆ
A2: ĐOÀN TRƯỜNG THPT NGUYỄN HUỆ
A4: PHONG TRÀO SỐ 2 - KHỐI 10 TỪ NGÀY 27/10/2025 ĐẾN NGÀY 09/01/2026
A7: Khối 10 | B7: Tuần 9+10+11 | C7: Tuần 12+13 | D7: Tuần 14 | E7: Tuần 15 | F7: Tuần 16 | G7: Tuần 17 | H7: Tuần 18+19 | I7: Trung bình | J7: Vị thứ
A8: 45667 | B8: ='Lớp 10'!S231 -> 296 | C8: ='Lớp 10'!S265 -> 297 | D8: ='Lớp 10'!S297 -> 298.5 | E8: ='Lớp 10'!S330 -> 301.5 | F8: ='Lớp 10'!S367 -> 298.5 | G8: ='Lớp 10'!S400 -> 299.5 | H8: ='Lớp 10'!S432 -> 299 | I8: =ROUND(AVERAGE(B8:H8),2) -> 298.57 | J8: =RANK(I8,$I$8:$I$19,0) -> 8
A9: 45698 | B9: ='Lớp 10'!S232 -> 299 | C9: ='Lớp 10'!S266 -> 297.5 | D9: ='Lớp 10'!S298 -> 299.5 | E9: ='Lớp 10'!S331 -> 303 | F9: ='Lớp 10'!S368 -> 300.5 | G9: ='Lớp 10'!S401 -> 300.5 | H9: ='Lớp 10'!S433 -> 299 | I9: =ROUND(AVERAGE(B9:H9),2) -> 299.86 | J9: =RANK(I9,$I$8:$I$19,0) -> 4
A10: 45726 | B10: ='Lớp 10'!S233 -> 299 | C10: ='Lớp 10'!S267 -> 294.5 | D10: ='Lớp 10'!S299 -> 300 | E10: ='Lớp 10'!S332 -> 302.5 | F10: ='Lớp 10'!S369 -> 301 | G10: ='Lớp 10'!S402 -> 300 | H10: ='Lớp 10'!S434 -> 299.5 | I10: =ROUND(AVERAGE(B10:H10),2) -> 299.5 | J10: =RANK(I10,$I$8:$I$19,0) -> 5
A11: 45757 | B11: ='Lớp 10'!S234 -> 299.5 | C11: ='Lớp 10'!S268 -> 300 | D11: ='Lớp 10'!S300 -> 297.5 | E11: ='Lớp 10'!S333 -> 299.5 | F11: ='Lớp 10'!S370 -> 299 | G11: ='Lớp 10'!S403 -> 300.5 | H11: ='Lớp 10'!S435 -> 299.5 | I11: =ROUND(AVERAGE(B11:H11),2) -> 299.36 | J11: =RANK(I11,$I$8:$I$19,0) -> 6
A12: 45787 | B12: ='Lớp 10'!S235 -> 298 | C12: ='Lớp 10'!S269 -> 298.5 | D12: ='Lớp 10'!S301 -> 298.5 | E12: ='Lớp 10'!S334 -> 299.5 | F12: ='Lớp 10'!S371 -> 295 | G12: ='Lớp 10'!S404 -> 298.5 | H12: ='Lớp 10'!S436 -> 298.5 | I12: =ROUND(AVERAGE(B12:H12),2) -> 298.07 | J12: =RANK(I12,$I$8:$I$19,0) -> 11
A13: 45818 | B13: ='Lớp 10'!S236 -> 296 | C13: ='Lớp 10'!S270 -> 297 | D13: ='Lớp 10'!S302 -> 302 | E13: ='Lớp 10'!S335 -> 300.5 | F13: ='Lớp 10'!S372 -> 300 | G13: ='Lớp 10'!S405 -> 296 | H13: ='Lớp 10'!S437 -> 298.5 | I13: =ROUND(AVERAGE(B13:H13),2) -> 298.57 | J13: =RANK(I13,$I$8:$I$19,0) -> 8
A14: 45848 | B14: ='Lớp 10'!S237 -> 300 | C14: ='Lớp 10'!S271 -> 300 | D14: ='Lớp 10'!S303 -> 300 | E14: ='Lớp 10'!S336 -> 301.5 | F14: ='Lớp 10'!S373 -> 300 | G14: ='Lớp 10'!S406 -> 300 | H14: ='Lớp 10'!S438 -> 300.5 | I14: =ROUND(AVERAGE(B14:H14),2) -> 300.29 | J14: =RANK(I14,$I$8:$I$19,0) -> 3
A15: 45879 | B15: ='Lớp 10'!S238 -> 297.5 | C15: ='Lớp 10'!S272 -> 300 | D15: ='Lớp 10'!S304 -> 302 | E15: ='Lớp 10'!S337 -> 304 | F15: ='Lớp 10'!S374 -> 299.5 | G15: ='Lớp 10'!S407 -> 301 | H15: ='Lớp 10'!S439 -> 303 | I15: =ROUND(AVERAGE(B15:H15),2) -> 301 | J15: =RANK(I15,$I$8:$I$19,0) -> 1
A16: 45910 | B16: ='Lớp 10'!S239 -> 298 | C16: ='Lớp 10'!S273 -> 298 | D16: ='Lớp 10'!S305 -> 296 | E16: ='Lớp 10'!S338 -> 299.5 | F16: ='Lớp 10'!S375 -> 299 | G16: ='Lớp 10'!S408 -> 298.5 | H16: ='Lớp 10'!S440 -> 301.5 | I16: =ROUND(AVERAGE(B16:H16),2) -> 298.64 | J16: =RANK(I16,$I$8:$I$19,0) -> 7
A17: 45940 | B17: ='Lớp 10'!S240 -> 298 | C17: ='Lớp 10'!S274 -> 294 | D17: ='Lớp 10'!S306 -> 294 | E17: ='Lớp 10'!S339 -> 302.5 | F17: ='Lớp 10'!S376 -> 299.5 | G17: ='Lớp 10'!S409 -> 299 | H17: ='Lớp 10'!S441 -> 301 | I17: =ROUND(AVERAGE(B17:H17),2) -> 298.29 | J17: =RANK(I17,$I$8:$I$19,0) -> 10
A18: 45971 | B18: ='Lớp 10'!S241 -> 296 | C18: ='Lớp 10'!S275 -> 297.5 | D18: ='Lớp 10'!S307 -> 295 | E18: ='Lớp 10'!S340 -> 294.5 | F18: ='Lớp 10'!S377 -> 298.5 | G18: ='Lớp 10'!S410 -> 291 | H18: ='Lớp 10'!S442 -> 298.5 | I18: =ROUND(AVERAGE(B18:H18),2) -> 295.86 | J18: =RANK(I18,$I$8:$I$19,0) -> 12
A19: 46001 | B19: ='Lớp 10'!S242 -> 296.5 | C19: ='Lớp 10'!S276 -> 300 | D19: ='Lớp 10'!S308 -> 301.5 | E19: ='Lớp 10'!S341 -> 302 | F19: ='Lớp 10'!S378 -> 300 | G19: ='Lớp 10'!S411 -> 301 | H19: ='Lớp 10'!S443 -> 302.5 | I19: =ROUND(AVERAGE(B19:H19),2) -> 300.5 | J19: =RANK(I19,$I$8:$I$19,0) -> 2
E21: TP. Huế, ngày 10 tháng 11 năm 2025
A22: XÁC NHẬN CỦA BGH | E22: T/M BCH ĐOÀN TRƯỜNG
A23: Hiệu trưởng | E23: Bí thư
A27: Đặng Đức Tuệ | E27: Dương Phước Dũng
A30: TRƯỜNG THPT NGUYỄN HUỆ
A31: ĐOÀN TRƯỜNG THPT NGUYỄN HUỆ
A33: PHONG TRÀO SỐ 2 - KHỐI 11 TỪ NGÀY 27/10/2025 ĐẾN NGÀY 09/01/2026
A36: Khối 11 | B36: Tuần 9+10+11 | C36: Tuần 12+13 | D36: Tuần 14 | E36: Tuần 15 | F36: Tuần 16 | G36: Tuần 17 | H36: Tuần 18+19 | I36: Trung bình | J36: Vị thứ
A37: 45668 | B37: ='Lớp 11'!S267 -> 300 | C37: ='Lớp 11'!S300 -> 299 | D37: ='Lớp 11'!S333 -> 300 | E37: ='Lớp 11'!S370 -> 303.5 | F37: ='Lớp 11'!S416 -> 301 | G37: ='Lớp 11'!S454 -> 301 | H37: ='Lớp 11'!S489 -> 301.5 | I37: =ROUND(AVERAGE(B37:H37),2) -> 300.86 | J37: =RANK(I37,$I$37:$I$50,0) -> 2
A38: 45699 | B38: ='Lớp 11'!S268 -> 300 | C38: ='Lớp 11'!S301 -> 299 | D38: ='Lớp 11'!S334 -> 299 | E38: ='Lớp 11'!S371 -> 303 | F38: ='Lớp 11'!S417 -> 298 | G38: ='Lớp 11'!S455 -> 300 | H38: ='Lớp 11'!S490 -> 300 | I38: =ROUND(AVERAGE(B38:H38),2) -> 299.86 | J38: =RANK(I38,$I$37:$I$50,0) -> 8
A39: 45727 | B39: ='Lớp 11'!S269 -> 299 | C39: ='Lớp 11'!S302 -> 294.5 | D39: ='Lớp 11'!S335 -> 300.5 | E39: ='Lớp 11'!S372 -> 300.5 | F39: ='Lớp 11'!S418 -> 300.5 | G39: ='Lớp 11'!S456 -> 299.5 | H39: ='Lớp 11'!S491 -> 300 | I39: =ROUND(AVERAGE(B39:H39),2) -> 299.21 | J39: =RANK(I39,$I$37:$I$50,0) -> 9
A40: 45758 | B40: ='Lớp 11'!S270 -> 299.5 | C40: ='Lớp 11'!S303 -> 299 | D40: ='Lớp 11'!S336 -> 299.5 | E40: ='Lớp 11'!S373 -> 302.5 | F40: ='Lớp 11'!S419 -> 301 | G40: ='Lớp 11'!S457 -> 298.5 | H40: ='Lớp 11'!S492 -> 300 | I40: =ROUND(AVERAGE(B40:H40),2) -> 300 | J40: =RANK(I40,$I$37:$I$50,0) -> 7
A41: 45788 | B41: ='Lớp 11'!S271 -> 297.5 | C41: ='Lớp 11'!S304 -> 298.5 | D41: ='Lớp 11'!S337 -> 302 | E41: ='Lớp 11'!S374 -> 303.5 | F41: ='Lớp 11'!S420 -> 300.5 | G41: ='Lớp 11'!S458 -> 301 | H41: ='Lớp 11'!S493 -> 302 | I41: =ROUND(AVERAGE(B41:H41),2) -> 300.71 | J41: =RANK(I41,$I$37:$I$50,0) -> 3
A42: 45819 | B42: ='Lớp 11'!S272 -> 295.5 | C42: ='Lớp 11'!S305 -> 296.5 | D42: ='Lớp 11'!S338 -> 294 | E42: ='Lớp 11'!S375 -> 290 | F42: ='Lớp 11'!S421 -> 295.5 | G42: ='Lớp 11'!S459 -> 296 | H42: ='Lớp 11'!S494 -> 299 | I42: =ROUND(AVERAGE(B42:H42),2) -> 295.21 | J42: =RANK(I42,$I$37:$I$50,0) -> 14
A43: 45849 | B43: ='Lớp 11'!S273 -> 297 | C43: ='Lớp 11'!S306 -> 298 | D43: ='Lớp 11'!S339 -> 300.5 | E43: ='Lớp 11'!S376 -> 300.5 | F43: ='Lớp 11'!S422 -> 297.5 | G43: ='Lớp 11'!S460 -> 300 | H43: ='Lớp 11'!S495 -> 300 | I43: =ROUND(AVERAGE(B43:H43),2) -> 299.07 | J43: =RANK(I43,$I$37:$I$50,0) -> 11
A44: 45880 | B44: ='Lớp 11'!S274 -> 296.5 | C44: ='Lớp 11'!S307 -> 298.5 | D44: ='Lớp 11'!S340 -> 294 | E44: ='Lớp 11'!S377 -> 300 | F44: ='Lớp 11'!S423 -> 297.5 | G44: ='Lớp 11'!S461 -> 295 | H44: ='Lớp 11'!S496 -> 299 | I44: =ROUND(AVERAGE(B44:H44),2) -> 297.21 | J44: =RANK(I44,$I$37:$I$50,0) -> 13
A45: 45911 | B45: ='Lớp 11'!S275 -> 295 | C45: ='Lớp 11'!S308 -> 298 | D45: ='Lớp 11'!S341 -> 302 | E45: ='Lớp 11'!S378 -> 300.5 | F45: ='Lớp 11'!S424 -> 300.5 | G45: ='Lớp 11'!S462 -> 298.5 | H45: ='Lớp 11'!S497 -> 300 | I45: =ROUND(AVERAGE(B45:H45),2) -> 299.21 | J45: =RANK(I45,$I$37:$I$50,0) -> 9
A46: 45941 | B46: ='Lớp 11'!S276 -> 300 | C46: ='Lớp 11'!S309 -> 300 | D46: ='Lớp 11'!S342 -> 302 | E46: ='Lớp 11'!S379 -> 304 | F46: ='Lớp 11'!S425 -> 299 | G46: ='Lớp 11'!S463 -> 303 | H46: ='Lớp 11'!S498 -> 300 | I46: =ROUND(AVERAGE(B46:H46),2) -> 301.14 | J46: =RANK(I46,$I$37:$I$50,0) -> 1
A47: 45972 | B47: ='Lớp 11'!S277 -> 299 | C47: ='Lớp 11'!S310 -> 300 | D47: ='Lớp 11'!S343 -> 301.5 | E47: ='Lớp 11'!S380 -> 302 | F47: ='Lớp 11'!S426 -> 300 | G47: ='Lớp 11'!S464 -> 299 | H47: ='Lớp 11'!S499 -> 300 | I47: =ROUND(AVERAGE(B47:H47),2) -> 300.21 | J47: =RANK(I47,$I$37:$I$50,0) -> 6
A48: 46002 | B48: ='Lớp 11'!S278 -> 300 | C48: ='Lớp 11'!S311 -> 300 | D48: ='Lớp 11'!S344 -> 301 | E48: ='Lớp 11'!S381 -> 303 | F48: ='Lớp 11'!S427 -> 300.5 | G48: ='Lớp 11'!S465 -> 300.5 | H48: ='Lớp 11'!S500 -> 299.5 | I48: =ROUND(AVERAGE(B48:H48),2) -> 300.64 | J48: =RANK(I48,$I$37:$I$50,0) -> 4
A49: 11/13 | B49: ='Lớp 11'!S279 -> 299 | C49: ='Lớp 11'!S312 -> 300 | D49: ='Lớp 11'!S345 -> 299.5 | E49: ='Lớp 11'!S382 -> 303.5 | F49: ='Lớp 11'!S428 -> 300 | G49: ='Lớp 11'!S466 -> 301 | H49: ='Lớp 11'!S501 -> 300.5 | I49: =ROUND(AVERAGE(B49:H49),2) -> 300.5 | J49: =RANK(I49,$I$37:$I$50,0) -> 5
A50: 11/14 | B50: ='Lớp 11'!S280 -> 297.5 | C50: ='Lớp 11'!S313 -> 298.5 | D50: ='Lớp 11'!S346 -> 297.5 | E50: ='Lớp 11'!S383 -> 301 | F50: ='Lớp 11'!S429 -> 297 | G50: ='Lớp 11'!S467 -> 299 | H50: ='Lớp 11'!S502 -> 299.5 | I50: =ROUND(AVERAGE(B50:H50),2) -> 298.57 | J50: =RANK(I50,$I$37:$I$50,0) -> 12
E52: TP. Huế, ngày 10 tháng 11 năm 2025
A53: XÁC NHẬN CỦA BGH | E53: T/M BCH ĐOÀN TRƯỜNG
...

Sheet SƠ KẾT HKI
A1: TRƯỜNG THPT NGUYỄN HUỆ
A2: ĐOÀN TRƯỜNG THPT NGUYỄN HUỆ
A4: SƠ KẾT THI ĐUA HỌC KÌ I - KHỐI 10 NĂM HỌC 2025 - 2026
A7: Khối 10 | B7: Tuần 1+2 | C7: Tuần 3 | D7: Tuần 4 | E7: Tuần 5 | F7: Tuần 6 | G7: Tuần 7 | H7: Tuần 8 | I7: Tuần 9+10+11 | J7: Tuần 12+13 | K7: Tuần 14 | L7: Tuần 15 | M7: Tuần 16 | N7: Tuần 17 | O7: Tuần 18+19 | P7: Trung bình | Q7: Vị thứ
A8: 45667 | B8: ='Lớp 10'!S8 -> 299.5 | C8: ='Lớp 10'!S40 -> 301.5 | D8: ='Lớp 10'!S74 -> 297.5 | E8: ='Lớp 10'!S106 -> 297 | F8: ='Lớp 10'!S140 -> 301 | G8: ='Lớp 10'!S167 -> 297 | H8: ='Lớp 10'!S200 -> 300 | I8: ='Lớp 10'!S231 -> 296 | J8: ='Lớp 10'!S265 -> 297 | K8: ='Lớp 10'!S297 -> 298.5 | L8: ='Lớp 10'!S330 -> 301.5 | M8: ='Lớp 10'!S367 -> 298.5 | N8: ='Lớp 10'!S400 -> 299.5 | O8: ='Lớp 10'!S432 -> 299 | P8: =ROUND(AVERAGE(B8:O8),2) -> 298.82 | Q8: =RANK(P8,$P$8:$P$19,0) -> 8
A9: 45698 | B9: ='Lớp 10'!S9 -> 299 | C9: ='Lớp 10'!S41 -> 302 | D9: ='Lớp 10'!S75 -> 300 | E9: ='Lớp 10'!S107 -> 301 | F9: ='Lớp 10'!S141 -> 301 | G9: ='Lớp 10'!S168 -> 298.5 | H9: ='Lớp 10'!S201 -> 299 | I9: ='Lớp 10'!S232 -> 299 | J9: ='Lớp 10'!S266 -> 297.5 | K9: ='Lớp 10'!S298 -> 299.5 | L9: ='Lớp 10'!S331 -> 303 | M9: ='Lớp 10'!S368 -> 300.5 | N9: ='Lớp 10'!S401 -> 300.5 | O9: ='Lớp 10'!S433 -> 299 | P9: =ROUND(AVERAGE(B9:O9),2) -> 299.96 | Q9: =RANK(P9,$P$8:$P$19,0) -> 4
A10: 45726 | B10: ='Lớp 10'!S10 -> 299.5 | C10: ='Lớp 10'!S42 -> 300.5 | D10: ='Lớp 10'!S76 -> 298 | E10: ='Lớp 10'!S108 -> 296 | F10: ='Lớp 10'!S142 -> 299 | G10: ='Lớp 10'!S169 -> 297 | H10: ='Lớp 10'!S202 -> 300 | I10: ='Lớp 10'!S233 -> 299 | J10: ='Lớp 10'!S267 -> 294.5 | K10: ='Lớp 10'!S299 -> 300 | L10: ='Lớp 10'!S332 -> 302.5 | M10: ='Lớp 10'!S369 -> 301 | N10: ='Lớp 10'!S402 -> 300 | O10: ='Lớp 10'!S434 -> 299.5 | P10: =ROUND(AVERAGE(B10:O10),2) -> 299.04 | Q10: =RANK(P10,$P$8:$P$19,0) -> 7
A11: 45757 | B11: ='Lớp 10'!S11 -> 297.5 | C11: ='Lớp 10'!S43 -> 301.5 | D11: ='Lớp 10'!S77 -> 299.5 | E11: ='Lớp 10'!S109 -> 299.5 | F11: ='Lớp 10'!S143 -> 299.5 | G11: ='Lớp 10'!S170 -> 298.5 | H11: ='Lớp 10'!S203 -> 299.5 | I11: ='Lớp 10'!S234 -> 299.5 | J11: ='Lớp 10'!S268 -> 300 | K11: ='Lớp 10'!S300 -> 297.5 | L11: ='Lớp 10'!S333 -> 299.5 | M11: ='Lớp 10'!S370 -> 299 | N11: ='Lớp 10'!S403 -> 300.5 | O11: ='Lớp 10'!S435 -> 299.5 | P11: =ROUND(AVERAGE(B11:O11),2) -> 299.36 | Q11: =RANK(P11,$P$8:$P$19,0) -> 5
A12: 45787 | B12: ='Lớp 10'!S12 -> 300 | C12: ='Lớp 10'!S44 -> 300.5 | D12: ='Lớp 10'!S78 -> 297.5 | E12: ='Lớp 10'!S110 -> 296.5 | F12: ='Lớp 10'!S144 -> 299.5 | G12: ='Lớp 10'!S171 -> 299.5 | H12: ='Lớp 10'!S204 -> 299 | I12: ='Lớp 10'!S235 -> 298 | J12: ='Lớp 10'!S269 -> 298.5 | K12: ='Lớp 10'!S301 -> 298.5 | L12: ='Lớp 10'!S334 -> 299.5 | M12: ='Lớp 10'!S371 -> 295 | N12: ='Lớp 10'!S404 -> 298.5 | O12: ='Lớp 10'!S436 -> 298.5 | P12: =ROUND(AVERAGE(B12:O12),2) -> 298.5 | Q12: =RANK(P12,$P$8:$P$19,0) -> 11
A13: 45818 | B13: ='Lớp 10'!S13 -> 299.5 | C13: ='Lớp 10'!S45 -> 298 | D13: ='Lớp 10'!S79 -> 299.5 | E13: ='Lớp 10'!S111 -> 299 | F13: ='Lớp 10'!S145 -> 300.5 | G13: ='Lớp 10'!S172 -> 298 | H13: ='Lớp 10'!S205 -> 297 | I13: ='Lớp 10'!S236 -> 296 | J13: ='Lớp 10'!S270 -> 297 | K13: ='Lớp 10'!S302 -> 302 | L13: ='Lớp 10'!S335 -> 300.5 | M13: ='Lớp 10'!S372 -> 300 | N13: ='Lớp 10'!S405 -> 296 | O13: ='Lớp 10'!S437 -> 298.5 | P13: =ROUND(AVERAGE(B13:O13),2) -> 298.68 | Q13: =RANK(P13,$P$8:$P$19,0) -> 10
A14: 45848 | B14: ='Lớp 10'!S14 -> 300 | C14: ='Lớp 10'!S46 -> 301 | D14: ='Lớp 10'!S80 -> 299 | E14: ='Lớp 10'!S112 -> 301 | F14: ='Lớp 10'!S146 -> 299 | G14: ='Lớp 10'!S173 -> 299.5 | H14: ='Lớp 10'!S206 -> 300 | I14: ='Lớp 10'!S237 -> 300 | J14: ='Lớp 10'!S271 -> 300 | K14: ='Lớp 10'!S303 -> 300 | L14: ='Lớp 10'!S336 -> 301.5 | M14: ='Lớp 10'!S373 -> 300 | N14: ='Lớp 10'!S406 -> 300 | O14: ='Lớp 10'!S438 -> 300.5 | P14: =ROUND(AVERAGE(B14:O14),2) -> 300.11 | Q14: =RANK(P14,$P$8:$P$19,0) -> 2
A15: 45879 | B15: ='Lớp 10'!S15 -> 300 | C15: ='Lớp 10'!S47 -> 302.5 | D15: ='Lớp 10'!S81 -> 299.5 | E15: ='Lớp 10'!S113 -> 296 | F15: ='Lớp 10'!S147 -> 301 | G15: ='Lớp 10'!S174 -> 300 | H15: ='Lớp 10'!S207 -> 300 | I15: ='Lớp 10'!S238 -> 297.5 | J15: ='Lớp 10'!S272 -> 300 | K15: ='Lớp 10'!S304 -> 302 | L15: ='Lớp 10'!S337 -> 304 | M15: ='Lớp 10'!S374 -> 299.5 | N15: ='Lớp 10'!S407 -> 301 | O15: ='Lớp 10'!S439 -> 303 | P15: =ROUND(AVERAGE(B15:O15),2) -> 300.43 | Q15: =RANK(P15,$P$8:$P$19,0) -> 1
A16: 45910 | B16: ='Lớp 10'!S16 -> 300 | C16: ='Lớp 10'!S48 -> 298.5 | D16: ='Lớp 10'!S82 -> 296 | E16: ='Lớp 10'!S114 -> 300 | F16: ='Lớp 10'!S148 -> 300.5 | G16: ='Lớp 10'!S175 -> 298 | H16: ='Lớp 10'!S208 -> 300 | I16: ='Lớp 10'!S239 -> 298 | J16: ='Lớp 10'!S273 -> 298 | K16: ='Lớp 10'!S305 -> 296 | L16: ='Lớp 10'!S338 -> 299.5 | M16: ='Lớp 10'!S375 -> 299 | N16: ='Lớp 10'!S408 -> 298.5 | O16: ='Lớp 10'!S440 -> 301.5 | P16: =ROUND(AVERAGE(B16:O16),2) -> 298.82 | Q16: =RANK(P16,$P$8:$P$19,0) -> 8
A17: 45940 | B17: ='Lớp 10'!S17 -> 299.5 | C17: ='Lớp 10'!S49 -> 302 | D17: ='Lớp 10'!S83 -> 299.5 | E17: ='Lớp 10'!S115 -> 302.5 | F17: ='Lớp 10'!S149 -> 298.5 | G17: ='Lớp 10'!S176 -> 299 | H17: ='Lớp 10'!S209 -> 299 | I17: ='Lớp 10'!S240 -> 298 | J17: ='Lớp 10'!S274 -> 294 | K17: ='Lớp 10'!S306 -> 294 | L17: ='Lớp 10'!S339 -> 302.5 | M17: ='Lớp 10'!S376 -> 299.5 | N17: ='Lớp 10'!S409 -> 299 | O17: ='Lớp 10'!S441 -> 301 | P17: =ROUND(AVERAGE(B17:O17),2) -> 299.14 | Q17: =RANK(P17,$P$8:$P$19,0) -> 6
A18: 45971 | B18: ='Lớp 10'!S18 -> 299 | C18: ='Lớp 10'!S50 -> 298 | D18: ='Lớp 10'!S84 -> 297.5 | E18: ='Lớp 10'!S116 -> 299 | F18: ='Lớp 10'!S150 -> 300 | G18: ='Lớp 10'!S177 -> 299.5 | H18: ='Lớp 10'!S210 -> 299.5 | I18: ='Lớp 10'!S241 -> 296 | J18: ='Lớp 10'!S275 -> 297.5 | K18: ='Lớp 10'!S307 -> 295 | L18: ='Lớp 10'!S340 -> 294.5 | M18: ='Lớp 10'!S377 -> 298.5 | N18: ='Lớp 10'!S410 -> 291 | O18: ='Lớp 10'!S442 -> 298.5 | P18: =ROUND(AVERAGE(B18:O18),2) -> 297.39 | Q18: =RANK(P18,$P$8:$P$19,0) -> 12
A19: 46001 | B19: ='Lớp 10'!S19 -> 300.5 | C19: ='Lớp 10'!S51 -> 300 | D19: ='Lớp 10'!S85 -> 298.5 | E19: ='Lớp 10'!S117 -> 298.5 | F19: ='Lớp 10'!S151 -> 301 | G19: ='Lớp 10'!S178 -> 299.5 | H19: ='Lớp 10'!S211 -> 300 | I19: ='Lớp 10'!S242 -> 296.5 | J19: ='Lớp 10'!S276 -> 300 | K19: ='Lớp 10'!S308 -> 301.5 | L19: ='Lớp 10'!S341 -> 302 | M19: ='Lớp 10'!S378 -> 300 | N19: ='Lớp 10'!S411 -> 301 | O19: ='Lớp 10'!S443 -> 302.5 | P19: =ROUND(AVERAGE(B19:O19),2) -> 300.11 | Q19: =RANK(P19,$P$8:$P$19,0) -> 2
B21: KHUNG | D21: GỒM CÁC LỚP | H21: TỈ LỆ
B22: I | D22: 10/8; 10/7; 10/2; 10/12; 10/4; 10/10; 10/3; 10/9; 10/1; 10/6 | H22: 95-100%
B23: II | D23: 10/5; 10/11 | H23: 90-95%
N25: TP. Huế, ngày ..... tháng ...... năm 2026
E26: XÁC NHẬN CỦA BGH | N26: T/M BCH ĐOÀN TRƯỜNG
E27: Hiệu trưởng | N27: Bí thư
E33: Đặng Đức Tuệ | N33: Dương Phước Dũng
A36: TRƯỜNG THPT NGUYỄN HUỆ
A37: ĐOÀN TRƯỜNG THPT NGUYỄN HUỆ
A39: SƠ KẾT THI ĐUA HỌC KÌ I - KHỐI 11 NĂM HỌC 2025 - 2026
A42: Khối 11 | B42: Tuần 1+2 | C42: Tuần 3 | D42: Tuần 4 | E42: Tuần 5 | F42: Tuần 6 | G42: Tuần 7 | H42: Tuần 8 | I42: Tuần 9+10+11 | J42: Tuần 12+13 | K42: Tuần 14 | L42: Tuần 15 | M42: Tuần 16 | N42: Tuần 17 | O42: Tuần 18+19 | P42: Trung bình | Q42: Vị thứ
A43: 45668 | B43: ='Lớp 11'!S8 -> 300.5 | C43: ='Lớp 11'!S48 -> 300.5 | D43: ='Lớp 11'!S86 -> 298 | E43: ='Lớp 11'!S124 -> 302 | F43: ='Lớp 11'!S161 -> 301 | G43: ='Lớp 11'!S197 -> 300.5 | H43: ='Lớp 11'!S233 -> 301.5 | I43: ='Lớp 11'!S267 -> 300 | J43: ='Lớp 11'!S300 -> 299 | K43: ='Lớp 11'!S333 -> 300 | L43: ='Lớp 11'!S370 -> 303.5 | M43: ='Lớp 11'!S416 -> 301 | N43: ='Lớp 11'!S454 -> 301 | O43: ='Lớp 11'!S489 -> 301.5 | P43: =ROUND(AVERAGE(B43:O43),2) -> 300.71 | Q43: =RANK(P43,$P$43:$P$56,0) -> 3
A44: 45699 | B44: ='Lớp 11'!S9 -> 300 | C44: ='Lớp 11'!S49 -> 302.5 | D44: ='Lớp 11'!S87 -> 298.5 | E44: ='Lớp 11'!S125 -> 300 | F44: ='Lớp 11'!S162 -> 298.5 | G44: ='Lớp 11'!S198 -> 301 | H44: ='Lớp 11'!S234 -> 300 | I44: ='Lớp 11'!S268 -> 300 | J44: ='Lớp 11'!S301 -> 299 | K44: ='Lớp 11'!S334 -> 299 | L44: ='Lớp 11'!S371 -> 303 | M44: ='Lớp 11'!S417 -> 298 | N44: ='Lớp 11'!S455 -> 300 | O44: ='Lớp 11'!S490 -> 300 | P44: =ROUND(AVERAGE(B44:O44),2) -> 299.96 | Q44: =RANK(P44,$P$43:$P$56,0) -> 9
A45: 45727 | B45: ='Lớp 11'!S10 -> 299 | C45: ='Lớp 11'!S50 -> 302.5 | D45: ='Lớp 11'!S88 -> 298 | E45: ='Lớp 11'!S126 -> 307 | F45: ='Lớp 11'!S163 -> 298.5 | G45: ='Lớp 11'!S199 -> 302 | H45: ='Lớp 11'!S235 -> 299.5 | I45: ='Lớp 11'!S269 -> 299 | J45: ='Lớp 11'!S302 -> 294.5 | K45: ='Lớp 11'!S335 -> 300.5 | L45: ='Lớp 11'!S372 -> 300.5 | M45: ='Lớp 11'!S418 -> 300.5 | N45: ='Lớp 11'!S456 -> 299.5 | O45: ='Lớp 11'!S491 -> 300 | P45: =ROUND(AVERAGE(B45:O45),2) -> 300.07 | Q45: =RANK(P45,$P$43:$P$56,0) -> 8
A46: 45758 | B46: ='Lớp 11'!S11 -> 300 | C46: ='Lớp 11'!S51 -> 304 | D46: ='Lớp 11'!S89 -> 299.5 | E46: ='Lớp 11'!S127 -> 301.5 | F46: ='Lớp 11'!S164 -> 298 | G46: ='Lớp 11'!S200 -> 303 | H46: ='Lớp 11'!S236 -> 300.5 | I46: ='Lớp 11'!S270 -> 299.5 | J46: ='Lớp 11'!S303 -> 299 | K46: ='Lớp 11'!S336 -> 299.5 | L46: ='Lớp 11'!S373 -> 302.5 | M46: ='Lớp 11'!S419 -> 301 | N46: ='Lớp 11'!S457 -> 298.5 | O46: ='Lớp 11'!S492 -> 300 | P46: =ROUND(AVERAGE(B46:O46),2) -> 300.46 | Q46: =RANK(P46,$P$43:$P$56,0) -> 6
A47: 45788 | B47: ='Lớp 11'!S12 -> 300 | C47: ='Lớp 11'!S52 -> 302.5 | D47: ='Lớp 11'!S90 -> 300.5 | E47: ='Lớp 11'!S128 -> 301 | F47: ='Lớp 11'!S165 -> 301 | G47: ='Lớp 11'!S201 -> 300.5 | H47: ='Lớp 11'!S237 -> 301 | I47: ='Lớp 11'!S271 -> 297.5 | J47: ='Lớp 11'!S304 -> 298.5 | K47: ='Lớp 11'!S337 -> 302 | L47: ='Lớp 11'!S374 -> 303.5 | M47: ='Lớp 11'!S420 -> 300.5 | N47: ='Lớp 11'!S458 -> 301 | O47: ='Lớp 11'!S493 -> 302 | P47: =ROUND(AVERAGE(B47:O47),2) -> 300.82 | Q47: =RANK(P47,$P$43:$P$56,0) -> 2
A48: 45819 | B48: ='Lớp 11'!S13 -> 295 | C48: ='Lớp 11'!S53 -> 294.5 | D48: ='Lớp 11'!S91 -> 297.5 | E48: ='Lớp 11'!S129 -> 297 | F48: ='Lớp 11'!S166 -> 289.5 | G48: ='Lớp 11'!S202 -> 299.5 | H48: ='Lớp 11'!S238 -> 298.5 | I48: ='Lớp 11'!S272 -> 295.5 | J48: ='Lớp 11'!S305 -> 296.5 | K48: ='Lớp 11'!S338 -> 294 | L48: ='Lớp 11'!S375 -> 290 | M48: ='Lớp 11'!S421 -> 295.5 | N48: ='Lớp 11'!S459 -> 296 | O48: ='Lớp 11'!S494 -> 299 | P48: =ROUND(AVERAGE(B48:O48),2) -> 295.57 | Q48: =RANK(P48,$P$43:$P$56,0) -> 14
A49: 45849 | B49: ='Lớp 11'!S14 -> 300 | C49: ='Lớp 11'!S54 -> 301.5 | D49: ='Lớp 11'!S92 -> 298.5 | E49: ='Lớp 11'!S130 -> 300.5 | F49: ='Lớp 11'!S167 -> 299.5 | G49: ='Lớp 11'!S203 -> 300.5 | H49: ='Lớp 11'!S239 -> 302.5 | I49: ='Lớp 11'!S273 -> 297 | J49: ='Lớp 11'!S306 -> 298 | K49: ='Lớp 11'!S339 -> 300.5 | L49: ='Lớp 11'!S376 -> 300.5 | M49: ='Lớp 11'!S422 -> 297.5 | N49: ='Lớp 11'!S460 -> 300 | O49: ='Lớp 11'!S495 -> 300 | P49: =ROUND(AVERAGE(B49:O49),2) -> 299.75 | Q49: =RANK(P49,$P$43:$P$56,0) -> 10
A50: 45880 | B50: ='Lớp 11'!S15 -> 298.5 | C50: ='Lớp 11'!S55 -> 300.5 | D50: ='Lớp 11'!S93 -> 297.5 | E50: ='Lớp 11'!S131 -> 299.5 | F50: ='Lớp 11'!S168 -> 300.5 | G50: ='Lớp 11'!S204 -> 299 | H50: ='Lớp 11'!S240 -> 299.5 | I50: ='Lớp 11'!S274 -> 296.5 | J50: ='Lớp 11'!S307 -> 298.5 | K50: ='Lớp 11'!S340 -> 294 | L50: ='Lớp 11'!S377 -> 300 | M50: ='Lớp 11'!S423 -> 297.5 | N50: ='Lớp 11'!S461 -> 295 | O50: ='Lớp 11'!S496 -> 299 | P50: =ROUND(AVERAGE(B50:O50),2) -> 298.25 | Q50: =RANK(P50,$P$43:$P$56,0) -> 13
A51: 45911 | B51: ='Lớp 11'!S16 -> 299.5 | C51: ='Lớp 11'!S56 -> 301 | D51: ='Lớp 11'!S94 -> 298 | E51: ='Lớp 11'!S132 -> 300.5 | F51: ='Lớp 11'!S169 -> 297.5 | G51: ='Lớp 11'!S205 -> 300.5 | H51: ='Lớp 11'!S241 -> 300 | I51: ='Lớp 11'!S275 -> 295 | J51: ='Lớp 11'!S308 -> 298 | K51: ='Lớp 11'!S341 -> 302 | L51: ='Lớp 11'!S378 -> 300.5 | M51: ='Lớp 11'!S424 -> 300.5 | N51: ='Lớp 11'!S462 -> 298.5 | O51: ='Lớp 11'!S497 -> 300 | P51: =ROUND(AVERAGE(B51:O51),2) -> 299.39 | Q51: =RANK(P51,$P$43:$P$56,0) -> 11
A52: 45941 | B52: ='Lớp 11'!S17 -> 299.5 | C52: ='Lớp 11'!S57 -> 302.5 | D52: ='Lớp 11'!S95 -> 299 | E52: ='Lớp 11'!S133 -> 302 | F52: ='Lớp 11'!S170 -> 300 | G52: ='Lớp 11'!S206 -> 301 | H52: ='Lớp 11'!S242 -> 303.5 | I52: ='Lớp 11'!S276 -> 300 | J52: ='Lớp 11'!S309 -> 300 | K52: ='Lớp 11'!S342 -> 302 | L52: ='Lớp 11'!S379 -> 304 | M52: ='Lớp 11'!S425 -> 299 | N52: ='Lớp 11'!S463 -> 303 | O52: ='Lớp 11'!S498 -> 300 | P52: =ROUND(AVERAGE(B52:O52),2) -> 301.11 | Q52: =RANK(P52,$P$43:$P$56,0) -> 1
A53: 45972 | B53: ='Lớp 11'!S18 -> 300 | C53: ='Lớp 11'!S58 -> 301 | D53: ='Lớp 11'!S96 -> 299 | E53: ='Lớp 11'!S134 -> 300.5 | F53: ='Lớp 11'!S171 -> 301 | G53: ='Lớp 11'!S207 -> 301.5 | H53: ='Lớp 11'!S243 -> 301.5 | I53: ='Lớp 11'!S277 -> 299 | J53: ='Lớp 11'!S310 -> 300 | K53: ='Lớp 11'!S343 -> 301.5 | L53: ='Lớp 11'!S380 -> 302 | M53: ='Lớp 11'!S426 -> 300 | N53: ='Lớp 11'!S464 -> 299 | O53: ='Lớp 11'!S499 -> 300 | P53: =ROUND(AVERAGE(B53:O53),2) -> 300.43 | Q53: =RANK(P53,$P$43:$P$56,0) -> 7
A54: 46002 | B54: ='Lớp 11'!S19 -> 297.5 | C54: ='Lớp 11'!S59 -> 302 | D54: ='Lớp 11'!S97 -> 298.5 | E54: ='Lớp 11'!S135 -> 301 | F54: ='Lớp 11'!S172 -> 301 | G54: ='Lớp 11'!S208 -> 301 | H54: ='Lớp 11'!S244 -> 301.5 | I54: ='Lớp 11'!S278 -> 300 | J54: ='Lớp 11'!S311 -> 300 | K54: ='Lớp 11'!S344 -> 301 | L54: ='Lớp 11'!S381 -> 303 | M54: ='Lớp 11'!S427 -> 300.5 | N54: ='Lớp 11'!S465 -> 300.5 | O54: ='Lớp 11'!S500 -> 299.5 | P54: =ROUND(AVERAGE(B54:O54),2) -> 300.5 | Q54: =RANK(P54,$P$43:$P$56,0) -> 5
A55: 11/13 | B55: ='Lớp 11'!S20 -> 299.5 | C55: ='Lớp 11'!S60 -> 302 | D55: ='Lớp 11'!S98 -> 299 | E55: ='Lớp 11'!S136 -> 301.5 | F55: ='Lớp 11'!S173 -> 301 | G55: ='Lớp 11'!S209 -> 300.5 | H55: ='Lớp 11'!S245 -> 301 | I55: ='Lớp 11'!S279 -> 299 | J55: ='Lớp 11'!S312 -> 300 | K55: ='Lớp 11'!S345 -> 299.5 | L55: ='Lớp 11'!S382 -> 303.5 | M55: ='Lớp 11'!S428 -> 300 | N55: ='Lớp 11'!S466 -> 301 | O55: ='Lớp 11'!S501 -> 300.5 | P55: =ROUND(AVERAGE(B55:O55),2) -> 300.57 | Q55: =RANK(P55,$P$43:$P$56,0) -> 4
...
